Traceback (most recent call last):
  File "/home/mfvargas/miniconda3/envs/curso-python-imn/lib/python3.9/site-packages/jupyter_cache/executors/utils.py", line 51, in single_nb_execution
    executenb(
  File "/home/mfvargas/miniconda3/envs/curso-python-imn/lib/python3.9/site-packages/nbclient/client.py", line 1117, in execute
    return NotebookClient(nb=nb, resources=resources, km=km, **kwargs).execute()
  File "/home/mfvargas/miniconda3/envs/curso-python-imn/lib/python3.9/site-packages/nbclient/util.py", line 78, in wrapped
    return just_run(coro(*args, **kwargs))
  File "/home/mfvargas/miniconda3/envs/curso-python-imn/lib/python3.9/site-packages/nbclient/util.py", line 57, in just_run
    return loop.run_until_complete(coro)
  File "/home/mfvargas/miniconda3/envs/curso-python-imn/lib/python3.9/asyncio/base_events.py", line 642, in run_until_complete
    return future.result()
  File "/home/mfvargas/miniconda3/envs/curso-python-imn/lib/python3.9/site-packages/nbclient/client.py", line 558, in async_execute
    await self.async_execute_cell(
  File "/home/mfvargas/miniconda3/envs/curso-python-imn/lib/python3.9/site-packages/nbclient/client.py", line 862, in async_execute_cell
    self._check_raise_for_error(cell, exec_reply)
  File "/home/mfvargas/miniconda3/envs/curso-python-imn/lib/python3.9/site-packages/nbclient/client.py", line 765, in _check_raise_for_error
    raise CellExecutionError.from_cell_and_msg(cell, exec_reply_content)
nbclient.exceptions.CellExecutionError: An error occurred while executing the following cell:
------------------
datos_belennosarita_x_nbi = datos_belennosarita(datos['DISTRITO'])['TOTAL'].sum()
------------------

[0;31m---------------------------------------------------------------------------[0m
[0;31mTypeError[0m                                 Traceback (most recent call last)
[0;32m/tmp/ipykernel_125017/2352647589.py[0m in [0;36m<module>[0;34m[0m
[0;32m----> 1[0;31m [0mdatos_belennosarita_x_nbi[0m [0;34m=[0m [0mdatos_belennosarita[0m[0;34m([0m[0mdatos[0m[0;34m[[0m[0;34m'DISTRITO'[0m[0;34m][0m[0;34m)[0m[0;34m[[0m[0;34m'TOTAL'[0m[0;34m][0m[0;34m.[0m[0msum[0m[0;34m([0m[0;34m)[0m[0;34m[0m[0;34m[0m[0m
[0m
[0;31mTypeError[0m: 'DataFrame' object is not callable
TypeError: 'DataFrame' object is not callable

