Traceback (most recent call last):
  File "/home/mfvargas/miniconda3/envs/curso-python-imn/lib/python3.9/site-packages/jupyter_cache/executors/utils.py", line 51, in single_nb_execution
    executenb(
  File "/home/mfvargas/miniconda3/envs/curso-python-imn/lib/python3.9/site-packages/nbclient/client.py", line 1117, in execute
    return NotebookClient(nb=nb, resources=resources, km=km, **kwargs).execute()
  File "/home/mfvargas/miniconda3/envs/curso-python-imn/lib/python3.9/site-packages/nbclient/util.py", line 78, in wrapped
    return just_run(coro(*args, **kwargs))
  File "/home/mfvargas/miniconda3/envs/curso-python-imn/lib/python3.9/site-packages/nbclient/util.py", line 57, in just_run
    return loop.run_until_complete(coro)
  File "/home/mfvargas/miniconda3/envs/curso-python-imn/lib/python3.9/asyncio/base_events.py", line 642, in run_until_complete
    return future.result()
  File "/home/mfvargas/miniconda3/envs/curso-python-imn/lib/python3.9/site-packages/nbclient/client.py", line 558, in async_execute
    await self.async_execute_cell(
  File "/home/mfvargas/miniconda3/envs/curso-python-imn/lib/python3.9/site-packages/nbclient/client.py", line 862, in async_execute_cell
    self._check_raise_for_error(cell, exec_reply)
  File "/home/mfvargas/miniconda3/envs/curso-python-imn/lib/python3.9/site-packages/nbclient/client.py", line 765, in _check_raise_for_error
    raise CellExecutionError.from_cell_and_msg(cell, exec_reply_content)
nbclient.exceptions.CellExecutionError: An error occurred while executing the following cell:
------------------
# Carga de datos de distritos de Costa Rica

# Desde un shapefile remoto comprimido
distritos = gpd.read_file("https://github.com/curso-python-imn/curso-python-imn.github.io/raw/main/datos/division-territorial/limite_politico_administrativo_region.zip", encoding = "utf-8")

# Desde un shapefile local descomprimido
# distritos = gpd.read_file("datos/division-territorial/LIMITE_POLITICO_ADMINISTRATIVO_region.shp")

# Desde un shapefile local comprimido
# distritos = gpd.read_file("zip://./datos/division-territorial/limite_politico_administrativo_region.zip")


distritos.plot()
------------------

[0;31m---------------------------------------------------------------------------[0m
[0;31mTypeError[0m                                 Traceback (most recent call last)
[0;32m/tmp/ipykernel_159386/363968639.py[0m in [0;36m<module>[0;34m[0m
[1;32m      2[0m [0;34m[0m[0m
[1;32m      3[0m [0;31m# Desde un shapefile remoto comprimido[0m[0;34m[0m[0;34m[0m[0m
[0;32m----> 4[0;31m [0mdistritos[0m [0;34m=[0m [0mgpd[0m[0;34m.[0m[0mread_file[0m[0;34m([0m[0;34m"https://github.com/curso-python-imn/curso-python-imn.github.io/raw/main/datos/division-territorial/limite_politico_administrativo_region.zip"[0m[0;34m,[0m [0mencoding[0m [0;34m=[0m [0;34m"utf-8"[0m[0;34m)[0m[0;34m[0m[0;34m[0m[0m
[0m[1;32m      5[0m [0;34m[0m[0m
[1;32m      6[0m [0;31m# Desde un shapefile local descomprimido[0m[0;34m[0m[0;34m[0m[0m

[0;32m~/miniconda3/envs/curso-python-imn/lib/python3.9/site-packages/geopandas/io/file.py[0m in [0;36m_read_file[0;34m(filename, bbox, mask, rows, **kwargs)[0m
[1;32m    158[0m [0;34m[0m[0m
[1;32m    159[0m     [0;32mwith[0m [0mfiona_env[0m[0;34m([0m[0;34m)[0m[0;34m:[0m[0;34m[0m[0;34m[0m[0m
[0;32m--> 160[0;31m         [0;32mwith[0m [0mreader[0m[0;34m([0m[0mpath_or_bytes[0m[0;34m,[0m [0;34m**[0m[0mkwargs[0m[0;34m)[0m [0;32mas[0m [0mfeatures[0m[0;34m:[0m[0;34m[0m[0;34m[0m[0m
[0m[1;32m    161[0m [0;34m[0m[0m
[1;32m    162[0m             [0;31m# In a future Fiona release the crs attribute of features will[0m[0;34m[0m[0;34m[0m[0m

[0;32m~/miniconda3/envs/curso-python-imn/lib/python3.9/site-packages/fiona/collection.py[0m in [0;36m__init__[0;34m(self, bytesbuf, **kwds)[0m
[1;32m    553[0m [0;34m[0m[0m
[1;32m    554[0m         [0;31m# Instantiate the parent class.[0m[0;34m[0m[0;34m[0m[0m
[0;32m--> 555[0;31m         super(BytesCollection, self).__init__(self.virtual_file, vsi=filetype,
[0m[1;32m    556[0m                                               encoding='utf-8', **kwds)
[1;32m    557[0m [0;34m[0m[0m

[0;31mTypeError[0m: fiona.collection.Collection.__init__() got multiple values for keyword argument 'encoding'
TypeError: fiona.collection.Collection.__init__() got multiple values for keyword argument 'encoding'

